<robot name="pendulum">
    <material name="Red">
        <color rgba=".9 .1 0 1"/>
    </material>
    <material name="Blue">
        <color rgba="0 0 1 1"/>
    </material>

    <joint name="pendulum_joint" type="continuous">
      <origin xyz="0 0.18 0.0" rpy="0 0 0"/>
      <axis xyz="0 0 1"/>
      <parent link="world"/>
      <child link="sphere"/>
      <dynamics damping="0.01"/>
      <limit effort="0" velocity="0"/>
      <safety_controller k_velocity="0"/>
    </joint>

    <link name="world">
      <inertial>
        <mass value="0" />
        <origin xyz="0.0 0.0 0" rpy="0 0 0" />
        <inertia  ixx="0" ixy="0" ixz="0"
                  iyy="0" iyz="0"
                  izz="0" />
      </inertial>
    </link>

    <link name="sphere">
      <inertial>
        <mass value="10.05" />
        <origin xyz="0.25 0 0" rpy="0 0 0" />
        <inertia  ixx="0.001" ixy="0.0" ixz="0.0"
                  iyy="0.001" iyz="0.0"
                  izz="0.001" />
      </inertial>
      <visual>
        <origin xyz="0.25 0 0" rpy="0 0 0" />
        <geometry>
          <sphere radius="0.03"/>
        </geometry>
        <material name="Blue" />
      </visual>
      <collision>
        <origin xyz="0 0 0.25" rpy="0 0 0" />
        <geometry>
          <sphere radius="0.03"/>
        </geometry>
      </collision>
    </link>

    <joint name="pendulum_fixed_joint" type="fixed">
      <origin xyz="0 0 0" rpy="0 0 0" />
      <parent link="sphere"/>
      <child link="rod"/>
    </joint>

    <link name="rod">
      <inertial>
        <mass value="0.001" />
        <origin xyz="0 0 0" rpy="0 0 0" />
        <inertia  ixx="0.001" ixy="0.0" ixz="0.0"
                  iyy="0.001" iyz="0.0"
                  izz="0.001" />
      </inertial>
      <visual>
        <origin xyz="0.125 0 0" rpy="0 1.5708 0" />
        <geometry>
          <cylinder radius="0.01" length="0.25"/>
        </geometry>
        <material name="Red" />
      </visual>
      <collision>
        <origin xyz="0 0 0.125" rpy="0 0 0" />
        <geometry>
          <cylinder radius="0.01" length="0.25"/>
        </geometry>
      </collision>
    </link>
</robot>
