<robot name="Draco">

  <link name="world">
    <inertial>
      <origin xyz="0 0 0" rpy="0 0 0" />
      <mass value="0.00000001" />
      <inertia ixx="0.00000001" ixy="0.00000001" ixz="0.00000001" iyy="0.00000001" iyz="0.00000001" izz="0.00000001" />
    </inertial>
  </link>

  <link name="basePosX">
    <inertial>
      <origin xyz="0 0 0" rpy="0 0 0" />
      <mass value="0.00000001" />
      <inertia ixx="0.00000001" ixy="0.00000001" ixz="0.00000001" iyy="0.00000001" iyz="0.00000001" izz="0.00000001" />
    </inertial>
  </link>

  <joint name="basePosX" type="prismatic">
    <origin xyz="0 0 0" rpy="0 0 0" />
    <parent link="world" />
    <child link="basePosX" />
    <axis xyz="1 0 0" />
    <limit effort="150.0" velocity="100.0" lower="-200." upper="200." />
  </joint>

  <link name="basePosY">
    <inertial>
      <origin xyz="0 0 0" rpy="0 0 0" />
      <mass value="0.00000001" />
      <inertia ixx="0.00000001" ixy="0.00000001" ixz="0.00000001" iyy="0.00000001" iyz="0.00000001" izz="0.00000001" />
    </inertial>
  </link>
  <joint name="basePosY" type="prismatic">
    <origin xyz="0 0 0" rpy="0 0 0" />
    <parent link="basePosX" />
    <child link="basePosY" />
    <axis xyz="0 1 0" />
    <limit effort="150.0" velocity="100.0" lower="-200." upper="200." />
  </joint>

  <link name="basePosZ">
    <inertial>
      <origin xyz="0 0 0" rpy="0 0 0" />
      <mass value="0.00000001" />
      <inertia ixx="0.00000001" ixy="0.00000001" ixz="0.00000001" iyy="0.00000001" iyz="0.00000001" izz="0.00000001" />
    </inertial>
  </link>
  <joint name="basePosZ" type="prismatic">
    <origin xyz="0 0 0" rpy="0 0 0" />
    <parent link="basePosY" />
    <child link="basePosZ" />
    <axis xyz="0 0 1" />
    <limit effort="150.0" velocity="100.0" lower="-200." upper="200." />
  </joint>

  <link name="baseRotZ">
    <inertial>
      <origin xyz="0 0 0" rpy="0 0 0" />
      <mass value="0.00000001" />
      <inertia ixx="0.00000001" ixy="0.00000001" ixz="0.00000001" iyy="0.00000001" iyz="0.00000001" izz="0.00000001" />
    </inertial>
  </link>
  <joint name="baseRotZ" type="continuous">
    <origin xyz="0 0 0" rpy="0 0 0" />
    <parent link="basePosZ" />
    <child link="baseRotZ" />
    <axis xyz="0 0 1" />
  </joint>

  <link name="baseRotY">
    <inertial>
      <origin xyz="0 0 0" rpy="0 0 0" />
      <mass value="0.00000001" />
      <inertia ixx="0.00000001" ixy="0.00000001" ixz="0.00000001" iyy="0.00000001" iyz="0.00000001" izz="0.00000001" />
    </inertial>
  </link>
  <joint name="baseRotY" type="continuous">
    <origin xyz="0 0 0" rpy="0 0 0" />
    <parent link="baseRotZ" />
    <child link="baseRotY" />
    <axis xyz="0 1 0" />
  </joint>

  <link name="Torso">
    <inertial>
      <origin xyz="-0.0133907728940907 0.000753510365864796 0.10783" rpy="0 0 0" />
      <mass value="9.67" />
      <inertia ixx="0.0585154591166426" ixy="-9.46724624145663E-05" ixz="-0.00614431919973963" iyy="0.0651574953784801" iyz="-0.000230611945696951" izz="0.0178352105631859" />
    </inertial>
    <visual>
      <origin xyz="-0.05 0 -0.0549" rpy="1.5708 0 1.5708" />
      <geometry>
        <mesh filename="meshes/torso_.dae" />
      </geometry>
      <!--<origin xyz="0 0 0.2951" rpy="0 0 0" />-->
      <!--<geometry>-->
        <!--<mesh filename="meshes/torso.dae" />-->
      <!--</geometry>-->
      <material name="">
        <color rgba="0.752941176470588 0.752941176470588 0.752941176470588 1" />
      </material>
    </visual>
    <collision>
      <origin xyz="0 0 -0.815" rpy="0 0 0" />
      <geometry>
        <cylinder radius="0.1" length="0.02"/>
      </geometry>
    </collision>
  </link>
  <joint name="baseRotX" type="continuous">
    <origin xyz="0 0 0" rpy="0 0 0" />
    <parent link="baseRotY" />
    <child link="Torso" />
    <axis xyz="1 0 0" />
  </joint>

  <link name="rTorsoLed">
    <inertial>
      <origin xyz="0 0 0" rpy="0 0 0" />
      <mass value="0.00001" />
      <inertia ixx="0.00001" ixy="0.00001" ixz="0.00001" iyy="0.00001" iyz="0.00001" izz="0.00001" />
    </inertial>
  </link>
  <joint name="rTorsoLed" type="fixed">
    <origin xyz="0.077 -0.0405 0.25" rpy="0 0 0" />
    <parent link="Torso" />
    <child link="rTorsoLed" />
  </joint>

  <link name="lTorsoLed">
    <inertial>
      <origin xyz="0 0 0" rpy="0 0 0" />
      <mass value="0.00001" />
      <inertia ixx="0.00001" ixy="0.00001" ixz="0.00001" iyy="0.00001" iyz="0.00001" izz="0.00001" />
    </inertial>
  </link>
  <joint name="lTorsoLed" type="fixed">
    <origin xyz="0.077 0.0405 0.25" rpy="0 0 0" />
    <parent link="Torso" />
    <child link="lTorsoLed" />
  </joint>

  <link name="cTorsoLed">
    <inertial>
      <origin xyz="0 0 0" rpy="0 0 0" />
      <mass value="0.00001" />
      <inertia ixx="0.00001" ixy="0.00001" ixz="0.00001" iyy="0.00001" iyz="0.00001" izz="0.00001" />
    </inertial>
  </link>
  <joint name="cTorsoLed" type="fixed">
    <origin xyz="0.077 0 0.05" rpy="0 0 0" />
    <parent link="Torso" />
    <child link="cTorsoLed" />
  </joint>

  <link name="lHipYaw">
    <inertial>
      <origin xyz="0 0.07 0.05" rpy="0 0 0" />
      <mass value="2.962" />
      <inertia ixx="0.0001" ixy="0.0001" ixz="0.0001" iyy="0.0001" iyz="0.0001" izz="0.0001" />
    </inertial>
    <visual>
      <origin xyz="0 0 0" rpy="0 0 0" />
      <geometry>
        <mesh filename="meshes/lHipYaw.dae" />
      </geometry>
      <material name="">
        <color rgba="0.898039215686275 0.917647058823529 0.929411764705882 1" />
      </material>
    </visual>
  </link>
  <joint name="lHipYaw" type="revolute">
    <origin xyz="-0.0222 0.0870 0.0" rpy="0 0 0" />
    <dynamics damping="0.5" />
    <parent link="Torso" />
    <child link="lHipYaw" />
    <axis xyz="0 0 1" />
    <limit effort="150" lower="-1.04" upper="1.04" velocity="25.0"/>
  </joint>
  <transmission name="lHipYaw" type="transmission_interface/SimpleTransmission">
    <actuator name="lHipYaw"/>
    <joint name="lHipYaw"/>
    <mechanicalReduction>1</mechanicalReduction>
  </transmission>

  <link name="lHipRoll">
    <inertial>
      <origin xyz="0 0.022 -0.02" rpy="0 0 0" />
      <mass value="0.408" />
      <inertia ixx="0.0001" ixy="0.0001" ixz="0.0001" iyy="0.0001" iyz="0.0001" izz="0.001" />
    </inertial>
    <visual>
      <origin xyz="0 0 0" rpy="0 0 0" />
      <geometry>
        <mesh filename="meshes/lHipRoll.dae" />
      </geometry>
      <material name="">
        <color rgba="0.898039215686275 0.917647058823529 0.929411764705882 1" />
      </material>
    </visual>
  </link>
  <joint name="lHipRoll" type="revolute">
    <origin xyz="0 0.07 -0.02" rpy="0 0 0" />
    <dynamics damping="0.5" />
    <parent link="lHipYaw" />
    <child link="lHipRoll" />
    <axis xyz="1 0 0" />
    <limit effort="150" lower="-0.52" upper="1.04" velocity="25.0"/>
  </joint>
  <transmission name="lHipRoll" type="transmission_interface/SimpleTransmission">
    <actuator name="lHipRoll"/>
    <joint name="lHipRoll"/>
    <mechanicalReduction>1</mechanicalReduction>
  </transmission>

  <link name="lHipPitch">
    <inertial>
      <origin xyz="0.0009 0.0066 -0.24" rpy="0 0 0" />
      <mass value="6.0" />
      <inertia ixx="0.0555" ixy="0.0001" ixz="0.0039" iyy="0.0595" iyz="0.0001" izz="0.0059" />
    </inertial>
    <visual>
      <origin xyz="0 0 0" rpy="0 0 0" />
      <geometry>
        <mesh filename="meshes/lHipPitch.dae" />
      </geometry>
      <material name="">
        <color rgba="0.752941176470588 0.752941176470588 0.752941176470588 1" />
      </material>
    </visual>
  </link>
  <joint name="lHipPitch" type="revolute">
    <origin xyz="0 0.010 -0.065" rpy="0 0 0" />
    <dynamics damping="0.5" />
    <parent link="lHipRoll" />
    <child link="lHipPitch" />
    <axis xyz="0 1 0" />
    <limit effort="150" lower="-1.04" upper="1.04" velocity="25.0"/>
  </joint>
  <transmission name="lHipPitch" type="transmission_interface/SimpleTransmission">
    <actuator name="lHipPitch"/>
    <joint name="lHipPitch"/>
    <mechanicalReduction>1</mechanicalReduction>
  </transmission>

  <link name="lKnee">
    <inertial>
      <origin xyz="0.0161 0.0167 -0.275" rpy="0 0 0" />
      <mass value="3.5" />
      <inertia ixx="0.0224" ixy="0.0001" ixz="-0.0005" iyy="0.0240" iyz="0.0001" izz="0.0016" />
    </inertial>
    <visual>
      <origin xyz="0 0 0" rpy="0 0 0" />
      <geometry>
        <mesh filename="meshes/lKnee.dae" />
      </geometry>
      <material name="">
        <color rgba="0.752941176470588 0.752941176470588 0.752941176470588 1" />
      </material>
    </visual>
  </link>
  <joint name="lKnee" type="revolute">
    <origin xyz="0 -0.0168 -0.48" rpy="0 0 0" />
    <dynamics damping="0.5" />
    <parent link="lHipPitch" />
    <child link="lKnee" />
    <axis xyz="0 1 0" />
    <limit effort="150" lower="0.0" upper="2.13" velocity="25.0"/>
  </joint>
  <transmission name="lKnee" type="transmission_interface/SimpleTransmission">
    <actuator name="lKnee"/>
    <joint name="lKnee"/>
    <mechanicalReduction>1</mechanicalReduction>
  </transmission>

  <link name="lAnkle">
    <inertial>
      <origin xyz="0.0108 0 -0.0443" rpy="0 0 0" />
      <mass value="0.4" />
      <inertia ixx="0.0001" ixy="0.0001" ixz="0.0001" iyy="0.0001" iyz="0.0001" izz="0.0001" />
    </inertial>
    <visual>
      <origin xyz="0 0 0" rpy="0 0 0" />
      <geometry>
        <mesh filename="meshes/lAnkle.dae" />
      </geometry>
      <material name="">
        <color rgba="0.898039215686275 0.917647058823529 0.929411764705882 1" />
      </material>
    </visual>
  </link>
  <joint name="lAnkle" type="revolute">
    <origin xyz="0.0011 0.0168 -0.48" rpy="0 -1.57 0" />
    <dynamics damping="0.5" />
    <parent link="lKnee" />
    <child link="lAnkle" />
    <axis xyz="0 1 0" />
    <limit effort="150" lower="0.901" upper="2.44" velocity="25.0"/>
  </joint>
  <transmission name="lAnkle" type="transmission_interface/SimpleTransmission">
    <actuator name="lAnkle"/>
    <joint name="lAnkle"/>
    <mechanicalReduction>1</mechanicalReduction>
  </transmission>

  <link name="lFootFront">
    <inertial>
      <origin xyz="0 0 0" rpy="0 0 0" />
      <mass value="0.00001" />
      <inertia ixx="0.00001" ixy="0.00001" ixz="0.00001" iyy="0.00001" iyz="0.00001" izz="0.00001" />
    </inertial>
    <!--<visual>-->
      <!--<origin xyz="0 0 0" rpy="0 0 0" />-->
      <!--<geometry>-->
        <!--<sphere radius="0.03"/>-->
      <!--</geometry>-->
    <!--</visual>-->
    <collision>
      <origin xyz="0 0 0" rpy="0 0 0" />
      <geometry>
        <sphere radius="0.03"/>
      </geometry>
    </collision>
  </link>
  <joint name="lFootFront" type="fixed">
    <origin xyz="0.08 0.005 -0.044" rpy="0 0 0" />
    <parent link="lAnkle" />
    <child link="lFootFront" />
  </joint>

  <link name="lFootFront2">
    <inertial>
      <origin xyz="0 0 0" rpy="0 0 0" />
      <mass value="0.00001" />
      <inertia ixx="0.00001" ixy="0.00001" ixz="0.00001" iyy="0.00001" iyz="0.00001" izz="0.00001" />
    </inertial>
    <!--<visual>-->
      <!--<origin xyz="0 0 0" rpy="0 0 0" />-->
      <!--<geometry>-->
        <!--<sphere radius="0.03"/>-->
      <!--</geometry>-->
    <!--</visual>-->
    <collision>
      <origin xyz="0 0 0" rpy="0 0 0" />
      <geometry>
        <sphere radius="0.03"/>
      </geometry>
    </collision>
  </link>
  <joint name="lFootFront2" type="fixed">
    <origin xyz="0.08 -0.005 -0.044" rpy="0 0 0" />
    <parent link="lAnkle" />
    <child link="lFootFront2" />
  </joint>

  <link name="lFootBack">
    <inertial>
      <origin xyz="0 0 0" rpy="0 0 0" />
      <mass value="0.00001" />
      <inertia ixx="0.00001" ixy="0.00001" ixz="0.00001" iyy="0.00001" iyz="0.00001" izz="0.00001" />
    </inertial>
    <!--<visual>-->
      <!--<origin xyz="0 0 0" rpy="0 0 0" />-->
      <!--<geometry>-->
        <!--<sphere radius="0.03"/>-->
      <!--</geometry>-->
    <!--</visual>-->
    <collision>
      <origin xyz="0 0 0" rpy="0 0 0" />
      <geometry>
        <sphere radius="0.03"/>
      </geometry>
    </collision>
  </link>
  <joint name="lFootBack" type="fixed">
    <origin xyz="-0.05 0.005 -0.044" rpy="0 0 0" />
    <parent link="lAnkle" />
    <child link="lFootBack" />
  </joint>

  <link name="lFootBack2">
    <inertial>
      <origin xyz="0 0 0" rpy="0 0 0" />
      <mass value="0.00001" />
      <inertia ixx="0.00001" ixy="0.00001" ixz="0.00001" iyy="0.00001" iyz="0.00001" izz="0.00001" />
    </inertial>
    <!--<visual>-->
      <!--<origin xyz="0 0 0" rpy="0 0 0" />-->
      <!--<geometry>-->
        <!--<sphere radius="0.03"/>-->
      <!--</geometry>-->
    <!--</visual>-->
    <collision>
      <origin xyz="0 0 0" rpy="0 0 0" />
      <geometry>
        <sphere radius="0.03"/>
      </geometry>
    </collision>
  </link>
  <joint name="lFootBack2" type="fixed">
    <origin xyz="-0.05 -0.005 -0.044" rpy="0 0 0" />
    <parent link="lAnkle" />
    <child link="lFootBack2" />
  </joint>

  <link name="lFootCenter">
    <inertial>
      <origin xyz="0 0 0" rpy="0 0 0" />
      <mass value="0.00001" />
      <inertia ixx="0.00001" ixy="0.00001" ixz="0.00001" iyy="0.00001" iyz="0.00001" izz="0.00001" />
    </inertial>
    <!--<visual>-->
      <!--<origin xyz="0 0 0" rpy="0 0 0" />-->
      <!--<geometry>-->
        <!--<sphere radius="0.01"/>-->
      <!--</geometry>-->
    <!--</visual>-->
  </link>
  <joint name="lFootCenter" type="fixed">
    <origin xyz="0.015 0 -0.059" rpy="0 0 0" />
    <parent link="lAnkle" />
    <child link="lFootCenter" />
  </joint>

  <link name="rHipYaw">
    <inertial>
      <origin xyz="0 -0.07 0.05" rpy="0 0 0" />
      <mass value="2.962" />
      <inertia ixx="0.0001" ixy="0.0001" ixz="0.0001" iyy="0.0001" iyz="0.0001" izz="0.0001" />
    </inertial>
    <visual>
      <origin xyz="0 0 0" rpy="0 0 0" />
      <geometry>
        <mesh filename="meshes/rHipYaw.dae" />
      </geometry>
      <material name="">
        <color rgba="0.898039215686275 0.917647058823529 0.929411764705882 1" />
      </material>
    </visual>
  </link>
  <joint name="rHipYaw" type="revolute">
    <origin xyz="-0.0222 -0.0870 0.0" rpy="0 0 0" />
    <dynamics damping="0.5" />
    <parent link="Torso" />
    <child link="rHipYaw" />
    <axis xyz="0 0 1" />
    <limit effort="150" lower="-1.04" upper="1.04" velocity="25.0"/>
  </joint>
  <transmission name="rHipYaw" type="transmission_interface/SimpleTransmission">
    <actuator name="rHipYaw"/>
    <joint name="rHipYaw"/>
    <mechanicalReduction>1</mechanicalReduction>
  </transmission>

  <link name="rHipRoll">
    <inertial>
      <origin xyz="0 -0.022 -0.02" rpy="0 0 0" />
      <mass value="0.408" />
      <inertia ixx="0.0001" ixy="0.0001" ixz="0.0001" iyy="0.0001" iyz="0.0001" izz="0.001" />
    </inertial>
    <visual>
      <origin xyz="0 0 0" rpy="0 0 0" />
      <geometry>
        <mesh filename="meshes/rHipRoll.dae" />
      </geometry>
      <material name="">
        <color rgba="0.898039215686275 0.917647058823529 0.929411764705882 1" />
      </material>
    </visual>
  </link>
  <joint name="rHipRoll" type="revolute">
    <origin xyz="0 -0.07 -0.02" rpy="0 0 0" />
    <dynamics damping="0.5" />
    <parent link="rHipYaw" />
    <child link="rHipRoll" />
    <axis xyz="1 0 0" />
    <limit effort="150" lower="-1.04" upper="0.52" velocity="25.0"/>
  </joint>
  <transmission name="rHipRoll" type="transmission_interface/SimpleTransmission">
    <actuator name="rHipRoll"/>
    <joint name="rHipRoll"/>
    <mechanicalReduction>1</mechanicalReduction>
  </transmission>

  <link name="rHipPitch">
    <inertial>
      <origin xyz="0.0009 0.0066 -0.24" rpy="0 0 0" />
      <mass value="6.0" />
      <inertia ixx="0.0555" ixy="0.0001" ixz="0.0039" iyy="0.0595" iyz="0.0001" izz="0.0059" />
    </inertial>
    <visual>
      <origin xyz="0 0 0" rpy="0 0 0" />
      <geometry>
        <mesh filename="meshes/rHipPitch.dae" />
      </geometry>
      <material name="">
        <color rgba="0.752941176470588 0.752941176470588 0.752941176470588 1" />
      </material>
    </visual>
  </link>
  <joint name="rHipPitch" type="revolute">
    <origin xyz="0 -0.01 -0.065" rpy="0 0 0" />
    <dynamics damping="0.5" />
    <parent link="rHipRoll" />
    <child link="rHipPitch" />
    <axis xyz="0 1 0" />
    <limit effort="150" lower="-1.04" upper="1.04" velocity="25.0"/>
  </joint>
  <transmission name="rHipPitch" type="transmission_interface/SimpleTransmission">
    <actuator name="rHipPitch"/>
    <joint name="rHipPitch"/>
    <mechanicalReduction>1</mechanicalReduction>
  </transmission>

  <link name="rKnee">
    <inertial>
      <origin xyz="-0.0161 -0.0168 -0.275" rpy="0 0 0" />
      <mass value="3.5" />
      <inertia ixx="0.0224" ixy="0.0001" ixz="-0.0005" iyy="0.0240" iyz="0.0001" izz="0.0016" />
    </inertial>
    <visual>
      <origin xyz="0 0 0" rpy="0 0 0" />
      <geometry>
        <mesh filename="meshes/rKnee.dae" />
      </geometry>
      <material name="">
        <color rgba="0.752941176470588 0.752941176470588 0.752941176470588 1" />
      </material>
    </visual>
  </link>
  <joint name="rKnee" type="revolute">
    <origin xyz="0 0.01675 -0.48" rpy="0 0 0" />
    <dynamics damping="0.5" />
    <parent link="rHipPitch" />
    <child link="rKnee" />
    <axis xyz="0 1 0" />
    <limit effort="150" lower="0.0" upper="2.13" velocity="25.0"/>
  </joint>
  <transmission name="rKnee" type="transmission_interface/SimpleTransmission">
    <actuator name="rKnee"/>
    <joint name="rKnee"/>
    <mechanicalReduction>1</mechanicalReduction>
  </transmission>

  <link name="rAnkle">
    <inertial>
      <origin xyz="0.0108 0 -0.0443" rpy="0 0 0" />
      <mass value="0.4" />
      <inertia ixx="0.0001" ixy="0.0001" ixz="0.0001" iyy="0.0001" iyz="0.0001" izz="0.0001" />
    </inertial>
    <visual>
      <origin xyz="0 0 0" rpy="0 0 0" />
      <geometry>
        <mesh filename="meshes/rAnkle.dae" />
      </geometry>
      <material name="">
        <color rgba="0.898039215686275 0.917647058823529 0.929411764705882 1" />
      </material>
    </visual>
  </link>
  <joint name="rAnkle" type="revolute">
    <origin xyz="0.0011 -0.0168 -0.48" rpy="0 -1.57 0" />
    <dynamics damping="0.5" />
    <parent link="rKnee" />
    <child link="rAnkle" />
    <axis xyz="0 1 0" />
    <limit effort="150" lower="0.901" upper="2.44" velocity="25.0"/>
  </joint>
  <transmission name="rAnkle" type="transmission_interface/SimpleTransmission">
    <actuator name="rAnkle"/>
    <joint name="rAnkle"/>
    <mechanicalReduction>1</mechanicalReduction>
  </transmission>

  <link name="rFootFront">
    <inertial>
      <origin xyz="0 0 0" rpy="0 0 0" />
      <mass value="0.00001" />
      <inertia ixx="0.00001" ixy="0.00001" ixz="0.00001" iyy="0.00001" iyz="0.00001" izz="0.00001" />
    </inertial>
    <!--<visual>-->
      <!--<origin xyz="0 0 0" rpy="0 0 0" />-->
      <!--<geometry>-->
        <!--<sphere radius="0.03"/>-->
      <!--</geometry>-->
    <!--</visual>-->
    <collision>
      <origin xyz="0 0 0" rpy="0 0 0" />
      <geometry>
        <sphere radius="0.03"/>
      </geometry>
    </collision>
  </link>
  <joint name="rFootFront" type="fixed">
    <origin xyz="0.08 -0.005 -0.044" rpy="0 0 0" />
    <parent link="rAnkle" />
    <child link="rFootFront" />
  </joint>

  <link name="rFootFront2">
    <inertial>
      <origin xyz="0 0 0" rpy="0 0 0" />
      <mass value="0.00001" />
      <inertia ixx="0.00001" ixy="0.00001" ixz="0.00001" iyy="0.00001" iyz="0.00001" izz="0.00001" />
    </inertial>
    <!--<visual>-->
      <!--<origin xyz="0 0 0" rpy="0 0 0" />-->
      <!--<geometry>-->
        <!--<sphere radius="0.03"/>-->
      <!--</geometry>-->
    <!--</visual>-->
    <collision>
      <origin xyz="0 0 0" rpy="0 0 0" />
      <geometry>
        <sphere radius="0.03"/>
      </geometry>
    </collision>
  </link>
  <joint name="rFootFront2" type="fixed">
    <origin xyz="0.08 0.005 -0.044" rpy="0 0 0" />
    <parent link="rAnkle" />
    <child link="rFootFront2" />
  </joint>


  <link name="rFootBack">
    <inertial>
      <origin xyz="0 0 0" rpy="0 0 0" />
      <mass value="0.00001" />
      <inertia ixx="0.00001" ixy="0.00001" ixz="0.00001" iyy="0.00001" iyz="0.00001" izz="0.00001" />
    </inertial>
    <!--<visual>-->
      <!--<origin xyz="0 0 0" rpy="0 0 0" />-->
      <!--<geometry>-->
        <!--<sphere radius="0.03"/>-->
      <!--</geometry>-->
    <!--</visual>-->
    <collision>
      <origin xyz="0 0 0" rpy="0 0 0" />
      <geometry>
        <sphere radius="0.03"/>
      </geometry>
    </collision>
  </link>
  <joint name="rFootBack" type="fixed">
    <origin xyz="-0.05 -0.005 -0.044" rpy="0 0 0" />
    <parent link="rAnkle" />
    <child link="rFootBack" />
  </joint>

  <link name="rFootBack2">
    <inertial>
      <origin xyz="0 0 0" rpy="0 0 0" />
      <mass value="0.00001" />
      <inertia ixx="0.00001" ixy="0.00001" ixz="0.00001" iyy="0.00001" iyz="0.00001" izz="0.00001" />
    </inertial>
    <!--<visual>-->
      <!--<origin xyz="0 0 0" rpy="0 0 0" />-->
      <!--<geometry>-->
        <!--<sphere radius="0.03"/>-->
      <!--</geometry>-->
    <!--</visual>-->
    <collision>
      <origin xyz="0 0 0" rpy="0 0 0" />
      <geometry>
        <sphere radius="0.03"/>
      </geometry>
    </collision>
  </link>
  <joint name="rFootBack2" type="fixed">
    <origin xyz="-0.05 0.005 -0.044" rpy="0 0 0" />
    <parent link="rAnkle" />
    <child link="rFootBack2" />
  </joint>


  <link name="rFootCenter">
    <inertial>
      <origin xyz="0 0 0" rpy="0 0 0" />
      <mass value="0.00001" />
      <inertia ixx="0.00001" ixy="0.00001" ixz="0.00001" iyy="0.00001" iyz="0.00001" izz="0.00001" />
    </inertial>
    <!--<visual>-->
      <!--<origin xyz="0 0 0" rpy="0 0 0" />-->
      <!--<geometry>-->
        <!--<sphere radius="0.01"/>-->
      <!--</geometry>-->
    <!--</visual>-->
  </link>
  <joint name="rFootCenter" type="fixed">
    <origin xyz="0.015 0 -0.059" rpy="0 0 0" />
    <parent link="rAnkle" />
    <child link="rFootCenter" />
  </joint>
</robot>
