<robot name="Draco">

  <link name="world">
    <inertial>
      <origin xyz="0 0 0" rpy="0 0 0" />
      <mass value="0.00000001" />
      <inertia ixx="0.00000001" ixy="0.00000001" ixz="0.00000001" iyy="0.00000001" iyz="0.00000001" izz="0.00000001" />
    </inertial>
  </link>

  <link name="torso">
    <inertial>
      <origin xyz="-0.0133907728940907 0.000753510365864796 -0.187273411666051" rpy="0 0 0" />
      <mass value="9.67" />
      <inertia ixx="0.0585154591166426" ixy="-9.46724624145663E-05" ixz="-0.00614431919973963" iyy="0.0651574953784801" iyz="-0.000230611945696951" izz="0.0178352105631859" />
    </inertial>
    <visual>
      <origin xyz="0 0 0" rpy="0 0 0" />
      <!--<geometry>-->
        <!--<mesh filename="meshes/torso.dae" />-->
      <!--</geometry>-->
      <material name="">
        <color rgba="0.752941176470588 0.752941176470588 0.752941176470588 1" />
      </material>
    </visual>
  </link>
  <joint name="baseRotX" type="floating">
    <origin xyz="0 0 0" rpy="0 0 0" />
    <parent link="world" />
    <child link="torso" />
    <!--<axis xyz="1 0 0" />-->
  </joint>

  <link name="lHipYaw">
    <inertial>
      <origin xyz="0 0.07 0.05" rpy="0 0 0" />
      <mass value="2.962" />
      <inertia ixx="0.0001" ixy="0.0001" ixz="0.0001" iyy="0.0001" iyz="0.0001" izz="0.0001" />
    </inertial>
    <visual>
      <origin xyz="0 0 0" rpy="0 0 0" />
      <geometry>
        <mesh filename="meshes/lHipYaw.dae" />
      </geometry>
      <material name="">
        <color rgba="0.898039215686275 0.917647058823529 0.929411764705882 1" />
      </material>
    </visual>
  </link>
  <joint name="lHipYaw" type="continuous">
    <origin xyz="-0.0222 0.0870 -0.2951" rpy="0 0 0" />
    <dynamics damping="0.0" />
    <parent link="torso" />
    <child link="lHipYaw" />
    <axis xyz="0 0 1" />
  </joint>

  <link name="lHipRoll">
    <inertial>
      <origin xyz="0 0.022 -0.02" rpy="0 0 0" />
      <mass value="0.408" />
      <inertia ixx="0.0001" ixy="0.0001" ixz="0.0001" iyy="0.0001" iyz="0.0001" izz="0.001" />
    </inertial>
    <visual>
      <origin xyz="0 0 0" rpy="0 0 0" />
      <geometry>
        <mesh filename="meshes/lHipRoll.dae" />
      </geometry>
      <material name="">
        <color rgba="0.898039215686275 0.917647058823529 0.929411764705882 1" />
      </material>
    </visual>
  </link>
  <joint name="lHipRoll" type="continuous">
    <origin xyz="0 0.07 -0.02" rpy="0 0 0" />
    <dynamics damping="0.0" />
    <parent link="lHipYaw" />
    <child link="lHipRoll" />
    <axis xyz="1 0 0" />
  </joint>

  <link name="lHipPitch">
    <inertial>
      <origin xyz="0.0009 0.0066 -0.24" rpy="0 0 0" />
      <mass value="6.0" />
      <inertia ixx="0.0555" ixy="0.0001" ixz="0.0039" iyy="0.0595" iyz="0.0001" izz="0.0059" />
    </inertial>
    <visual>
      <origin xyz="0 0 0" rpy="0 0 0" />
      <geometry>
        <mesh filename="meshes/lHipPitch.dae" />
      </geometry>
      <material name="">
        <color rgba="0.752941176470588 0.752941176470588 0.752941176470588 1" />
      </material>
    </visual>
  </link>
  <joint name="lHipPitch" type="continuous">
    <origin xyz="0 0.010 -0.065" rpy="0 0 0" />
    <dynamics damping="0.0" />
    <parent link="lHipRoll" />
    <child link="lHipPitch" />
    <axis xyz="0 1 0" />
  </joint>

  <link name="lKnee">
    <inertial>
      <origin xyz="0.0161 0.0167 -0.275" rpy="0 0 0" />
      <mass value="3.5" />
      <inertia ixx="0.0224" ixy="0.0001" ixz="-0.0005" iyy="0.0240" iyz="0.0001" izz="0.0016" />
    </inertial>
    <visual>
      <origin xyz="0 0 0" rpy="0 0 0" />
      <geometry>
        <mesh filename="meshes/lKnee.dae" />
      </geometry>
      <material name="">
        <color rgba="0.752941176470588 0.752941176470588 0.752941176470588 1" />
      </material>
    </visual>
  </link>
  <joint name="lKnee" type="continuous">
    <origin xyz="0 -0.0168 -0.48" rpy="0 0 0" />
    <dynamics damping="0.0" />
    <parent link="lHipPitch" />
    <child link="lKnee" />
    <axis xyz="0 1 0" />
  </joint>

  <link name="lAnkle">
    <inertial>
      <origin xyz="0.0108 0 -0.0443" rpy="0 0 0" />
      <mass value="0.7" />
      <inertia ixx="0.0001" ixy="0.0001" ixz="0.0001" iyy="0.0001" iyz="0.0001" izz="0.0001" />
    </inertial>
    <visual>
      <origin xyz="0 0 0" rpy="0 0 0" />
      <geometry>
        <mesh filename="meshes/lAnkle.dae" />
      </geometry>
      <material name="">
        <color rgba="0.898039215686275 0.917647058823529 0.929411764705882 1" />
      </material>
    </visual>
    <collision>
      <origin xyz="0.015 0 -0.05" rpy="0 0 0" />
      <geometry>
        <box size="0.15 0.04 0.03"/>
      </geometry>
    </collision>
  </link>
  <joint name="lAnkle" type="continuous">
    <origin xyz="0.0011 0.0168 -0.48" rpy="0 -1.57 0" />
    <dynamics damping="0.0" />
    <parent link="lKnee" />
    <child link="lAnkle" />
    <axis xyz="0 1 0" />
  </joint>

  <link name="rHipYaw">
    <inertial>
      <origin xyz="0 -0.07 0.05" rpy="0 0 0" />
      <mass value="2.962" />
      <inertia ixx="0.0001" ixy="0.0001" ixz="0.0001" iyy="0.0001" iyz="0.0001" izz="0.0001" />
    </inertial>
    <visual>
      <origin xyz="0 0 0" rpy="0 0 0" />
      <geometry>
        <mesh filename="meshes/rHipYaw.dae" />
      </geometry>
      <material name="">
        <color rgba="0.898039215686275 0.917647058823529 0.929411764705882 1" />
      </material>
    </visual>
  </link>
  <joint name="rHipYaw" type="continuous">
    <origin xyz="-0.0222 -0.0870 -0.2951" rpy="0 0 0" />
    <dynamics damping="0.0" />
    <parent link="torso" />
    <child link="rHipYaw" />
    <axis xyz="0 0 1" />
  </joint>

  <link name="rHipRoll">
    <inertial>
      <origin xyz="0 -0.022 -0.02" rpy="0 0 0" />
      <mass value="0.408" />
      <inertia ixx="0.0001" ixy="0.0001" ixz="0.0001" iyy="0.0001" iyz="0.0001" izz="0.001" />
    </inertial>
    <visual>
      <origin xyz="0 0 0" rpy="0 0 0" />
      <geometry>
        <mesh filename="meshes/rHipRoll.dae" />
      </geometry>
      <material name="">
        <color rgba="0.898039215686275 0.917647058823529 0.929411764705882 1" />
      </material>
    </visual>
  </link>
  <joint name="rHipRoll" type="continuous">
    <origin xyz="0 -0.07 -0.02" rpy="0 0 0" />
    <dynamics damping="0.0" />
    <parent link="rHipYaw" />
    <child link="rHipRoll" />
    <axis xyz="1 0 0" />
  </joint>

  <link name="rHipPitch">
    <inertial>
      <origin xyz="0.0009 0.0066 -0.24" rpy="0 0 0" />
      <mass value="6.0" />
      <inertia ixx="0.0555" ixy="0.0001" ixz="0.0039" iyy="0.0595" iyz="0.0001" izz="0.0059" />
    </inertial>
    <visual>
      <origin xyz="0 0 0" rpy="0 0 0" />
      <geometry>
        <mesh filename="meshes/rHipPitch.dae" />
      </geometry>
      <material name="">
        <color rgba="0.752941176470588 0.752941176470588 0.752941176470588 1" />
      </material>
    </visual>
  </link>
  <joint name="rHipPitch" type="continuous">
    <origin xyz="0 -0.01 -0.065" rpy="0 0 0" />
    <dynamics damping="0.0" />
    <parent link="rHipRoll" />
    <child link="rHipPitch" />
    <axis xyz="0 1 0" />
  </joint>

  <link name="rKnee">
    <inertial>
      <origin xyz="-0.0161 -0.0168 -0.275" rpy="0 0 0" />
      <mass value="3.5" />
      <inertia ixx="0.0224" ixy="0.0001" ixz="-0.0005" iyy="0.0240" iyz="0.0001" izz="0.0016" />
    </inertial>
    <visual>
      <origin xyz="0 0 0" rpy="0 0 0" />
      <geometry>
        <mesh filename="meshes/rKnee.dae" />
      </geometry>
      <material name="">
        <color rgba="0.752941176470588 0.752941176470588 0.752941176470588 1" />
      </material>
    </visual>
  </link>
  <joint name="rKnee" type="continuous">
    <origin xyz="0 0.01675 -0.48" rpy="0 0 0" />
    <dynamics damping="0.0" />
    <parent link="rHipPitch" />
    <child link="rKnee" />
    <axis xyz="0 1 0" />
  </joint>

  <link name="rAnkle">
    <inertial>
      <origin xyz="0.0108 0 -0.0443" rpy="0 0 0" />
      <mass value="0.7" />
      <inertia ixx="0.0001" ixy="0.0001" ixz="0.0001" iyy="0.0001" iyz="0.0001" izz="0.0001" />
    </inertial>
    <visual>
      <origin xyz="0 0 0" rpy="0 0 0" />
      <geometry>
        <mesh filename="meshes/rAnkle.dae" />
      </geometry>
      <material name="">
        <color rgba="0.898039215686275 0.917647058823529 0.929411764705882 1" />
      </material>
    </visual>
    <collision>
      <origin xyz="0.015 0 -0.05" rpy="0 0 0" />
      <geometry>
        <box size="0.15 0.04 0.03"/>
      </geometry>
    </collision>
  </link>
  <joint name="rAnkle" type="continuous">
    <origin xyz="0.0011 -0.0168 -0.48" rpy="0 -1.57 0" />
    <dynamics damping="0.0" />
    <parent link="rKnee" />
    <child link="rAnkle" />
    <axis xyz="0 1 0" />
  </joint>
</robot>
