<robot name="t1d">
  <link name="world" />
  <joint name="ground_joint" type="fixed">
      <origin xyz="0 0 0" rpy="0 0 0" />
      <parent link="world" />
      <child link="base_link" />
  </joint>
  <link
    name="base_link">
    <inertial>
      <origin
        xyz="-0.0482060307102544 0.0551118578455235 -0.193622379442082"
        rpy="0 0 0" />
      <mass
        value="1.91064938838114" />
      <inertia
        ixx="0.0042743435626202"
        ixy="0.00255843020092317"
        ixz="-0.000376548938045271"
        iyy="0.00296366226466246"
        iyz="0.000642708924518638"
        izz="0.00642434505077941" />
    </inertial>
    <visual>
      <origin
        xyz="0 0 0"
        rpy="0 0 0" />
      <geometry>
        <mesh
            filename="meshes/base_link.STL" />
      </geometry>
      <material
        name="">
        <color
          rgba="0.898039215686275 0.917647058823529 0.929411764705882 1" />
      </material>
    </visual>
    <!--<collision>-->
      <!--<origin-->
        <!--xyz="0 0 0"-->
        <!--rpy="0 0 0" />-->
      <!--<geometry>-->
        <!--<mesh-->
          <!--filename="meshes/base_link.STL" />-->
      <!--</geometry>-->
    <!--</collision>-->
  </link>
  <link
    name="first_link">
    <inertial>
      <origin
        xyz="0.0418757349036049 0.0161332536873584 -0.0628095000026898"
        rpy="0 0 0" />
      <mass
        value="1.40401696969463" />
      <inertia
        ixx="0.00449144161942821"
        ixy="0.000782046666871725"
        ixz="0.000925620253568016"
        iyy="0.00266108601216819"
        iyz="-0.000660928342822112"
        izz="0.00441270449554099" />
    </inertial>
    <visual>
      <origin
        xyz="0 0 0"
        rpy="0 0 0" />
      <geometry>
        <mesh
          filename="meshes/first_link.STL" />
      </geometry>
      <material
        name="">
        <color
          rgba="0.898039215686275 0.917647058823529 0.929411764705882 1" />
      </material>
    </visual>
    <!--<collision>-->
      <!--<origin-->
        <!--xyz="0 0 0"-->
        <!--rpy="0 0 0" />-->
      <!--<geometry>-->
        <!--<mesh-->
          <!--filename="meshes/first_link.STL" />-->
      <!--</geometry>-->
    <!--</collision>-->
  </link>
  <joint
    name="first_joint"
    type="revolute">
    <origin
      xyz="0 0.17 0.09778"
      rpy="1.5708 0 0" />
    <parent
      link="base_link" />
    <child
      link="first_link" />
    <axis
      xyz="0 0 1" />
    <limit
      effort="0"
      velocity="0" />
  </joint>
  <link
    name="second_link">
    <inertial>
      <origin
        xyz="-0.00198444979584683 0.129779108178935 -0.0488027759242751"
        rpy="0 0 0" />
      <mass
        value="7.25638056769983" />
      <inertia
        ixx="0.0844519435129101"
        ixy="-0.00141640996008577"
        ixz="0.000908992772492024"
        iyy="0.0183812004415471"
        iyz="-0.00343272706614484"
        izz="0.0923553973340477" />
    </inertial>
    <visual>
      <origin
        xyz="0 0 0"
        rpy="0 0 0" />
      <geometry>
        <mesh
          filename="meshes/second_link.STL" />
      </geometry>
      <material
        name="">
        <color
          rgba="0.898039215686275 0.917647058823529 0.929411764705882 1" />
      </material>
    </visual>
    <!--<collision>-->
      <!--<origin-->
        <!--xyz="0 0 0"-->
        <!--rpy="0 0 0" />-->
      <!--<geometry>-->
        <!--<mesh-->
          <!--filename="meshes/second_link.STL" />-->
      <!--</geometry>-->
    <!--</collision>-->
  </link>
  <joint
    name="second_joint"
    type="revolute">
    <origin
      xyz="0 0.10551 -0.03"
      rpy="0 0 0" />
    <parent
      link="first_link" />
    <child
      link="second_link" />
    <axis
      xyz="0 1 0" />
    <limit
      effort="0"
      velocity="0" />
  </joint>
  <link
    name="cuff">
    <inertial>
      <origin
        xyz="0 0 0"
        rpy="0 0 0" />
      <mass
        value="0.000001" />
      <inertia
        ixx="0.000001"
        ixy="0.000001"
        ixz="0.000001"
        iyy="0.000001"
        iyz="0.000001"
        izz="0.000001" />
    </inertial>
    <visual>
      <origin
        xyz="0 0 0"
        rpy="0 0 0" />
      <geometry>
        <box size="0.01 0.01 0.01" />
      </geometry>
      <material
        name="">
        <color
          rgba="0.898039215686275 0.917647058823529 0.929411764705882 1" />
      </material>
    </visual>
  </link>
  <joint
    name="third_joint"
    type="revolute">
    <origin
      xyz="0 0.25685 0.0167"
      rpy="0 0 0" />
    <parent
      link="second_link" />
    <child
      link="cuff" />
    <axis
      xyz="0 0 1" />
    <limit
      effort="0"
      velocity="0" />
  </joint>
</robot>
