<?xml version="1.0" encoding="utf-8"?>

<robot name="draco">

  <material name = "dark_gray">
    <color rgba="0.3 0.3 0.3 1"/>
  </material>

  <material name = "gray">
    <color rgba="0.5 0.5 0.5 1"/>
  </material>

  <material name = "light_blue">
    <color rgba="0.52 0.73 1 1"/>
  </material>

  <material name = "black">
    <color rgba="0 0 0 1"/>
  </material>

  <!--=============================== root (torso) ===========================-->
  <link name="torso_link">
    <visual>
      <origin rpy="0 -0 0" xyz="0 0 0"/>
      <geometry>
        <mesh filename="package://meshes/torso_link.stl"/>
      </geometry>
      <material name="gray"/>
    </visual>
    <inertial>
      <origin rpy="0 0 0" xyz="-31.658e-03 -0.03865e-03 125.19e-03"/>
      <mass value="6.456"/>
      <inertia ixx="178517.35e-06" ixy="-18.968e-06" ixz="28376.527e-06" iyy="181767.801e-06" iyz="-50.398e-06" izz="37147.31e-06"/>
    </inertial>
  </link>

  <!--=============================== torso_com (torso_com_link) ===========================-->
  <joint name="torso_com" type="fixed">
    <origin rpy="0 0 0" xyz="-31.658e-03 -0.03865e-03 125.19e-03"/>
    <parent link="torso_link"/>
    <child link="torso_com_link"/>
  </joint>
  <link name="torso_com_link">
    <inertial>
      <origin rpy="0 0 0" xyz="0 0 0"/>
      <mass value="1e-9"/>
      <inertia ixx="0" ixy="0" ixz="0" iyy="0" iyz="0" izz="0"/>
    </inertial>
  </link>

  <!--=============================== neck_pitch (neck_pitch_link) ===========================-->
  <joint name="neck_pitch" type="revolute">
    <origin rpy="0 0 0" xyz="-0.0025 0 0.352"/>
    <parent link="torso_link"/>
    <child link="neck_pitch_link"/>
    <axis xyz="0 1 0"/>
    <limit effort="8.8" lower="-0.523599" upper="1.309" velocity="76"/>
    <joint_properties friction="0.0"/>
  </joint>
  <link name="neck_pitch_link">
    <visual>
      <origin rpy="0 0 0" xyz="0 0 0"/>
      <geometry>
        <mesh filename="package://meshes/neck_pitch_link.stl"/>
      </geometry>
      <material name="dark_gray"/>
    </visual>
    <inertial>
      <origin rpy="0 0 0" xyz="0.0133603 -0.00105814 0.050"/>
      <mass value="1.394979"/>
      <inertia ixx="0.0026526" ixy="-2.37226e-05" ixz="-0.000179286" iyy="0.00218170" iyz="-10.85488e-05" izz="0.00312442"/>
    </inertial>
  </link>

  <!--=============================== l_shoulder_fe (l_shoulder_fe_link) ===========================-->
  <joint name="l_shoulder_fe" type="revolute">
    <origin rpy="0.523599 0 0" xyz="-0.05 0.156 0.2625"/>
    <parent link="torso_link"/>
    <child link="l_shoulder_fe_link"/>
    <axis xyz="0 1 0"/>
    <limit effort="18" lower="-2.26893" upper="0.698132" velocity="47"/>
    <joint_properties friction="0.0"/>
  </joint>
  <link name="l_shoulder_fe_link">
    <visual>
      <origin rpy="0 0 0" xyz="0 0 0"/>
      <geometry>
        <mesh filename="package://meshes/l_shoulder_fe_link.stl"/>
      </geometry>
      <material name="dark_gray"/>
    </visual>
    <inertial>
      <origin rpy="0 0 0" xyz="-0.0825089 -0.0272215 0"/>
      <mass value="1.02127"/>
      <inertia ixx="0.003" ixy="0.000188" ixz="-1.077e-04" iyy="0.002" iyz="-4.214e-07" izz="0.002"/>
    </inertial>
  </link>

  <!--=============================== l_shoulder_aa (l_shoulder_aa_link) ===========================-->
  <joint name="l_shoulder_aa" type="revolute">
    <origin rpy="-0.523599 0 0" xyz="0 0 0"/>
    <parent link="l_shoulder_fe_link"/>
    <child link="l_shoulder_aa_link"/>
    <axis xyz="1 0 0"/>
    <limit effort="18" lower="0" upper="2.0944" velocity="47"/>
    <joint_properties friction="0.0"/>
  </joint>
  <link name="l_shoulder_aa_link">
    <visual>
      <origin rpy="0 0 0" xyz="0 0 0"/>
      <geometry>
        <mesh filename="package://meshes/l_shoulder_aa_link.stl"/>
      </geometry>
      <material name="dark_gray"/>
    </visual>
    <inertial>
      <origin rpy="0 0 0" xyz="0.0189446 0.000135529 0.00688183"/>
      <mass value="0.880498"/>
      <inertia ixx="0.00104194" ixy="5.17675e-06" ixz="-0.000110264" iyy="0.00190054" iyz="6.87354e-06" izz="0.00224159"/>
    </inertial>
  </link>

  <!--=============================== l_shoulder_ie (l_shoulder_ie_link) ===========================-->
  <joint name="l_shoulder_ie" type="revolute">
    <origin rpy="0 0 0" xyz="0 0 0"/>
    <parent link="l_shoulder_aa_link"/>
    <child link="l_shoulder_ie_link"/>
    <axis xyz="0 0 1"/>
    <limit effort="18" lower="-1.55" upper="1.55" velocity="47"/>
    <joint_properties friction="0.0"/>
  </joint>
  <link name="l_shoulder_ie_link">
    <visual>
      <origin rpy="0 -0 0" xyz="0 0 0"/>
      <geometry>
        <mesh filename="package://meshes/l_shoulder_ie_link.stl"/>
      </geometry>
      <material name="gray"/>
    </visual>
    <inertial>
      <origin rpy="0 0 0" xyz="-0.00404627 0.029987 -0.137257"/>
      <mass value="1.21235"/>
      <inertia ixx="0.00490878" ixy="4.35994e-05" ixz="-6.63613e-05" iyy="0.00459797" iyz="3.61794e-05" izz="0.00207282"/>
    </inertial>
  </link>

  <!--=============================== l_elbow_fe (l_elbow_fe_link) ===========================-->
  <joint name="l_elbow_fe" type="revolute">
    <origin rpy="0 0 0" xyz="0 0 -0.25"/>
    <parent link="l_shoulder_ie_link"/>
    <child link="l_elbow_fe_link"/>
    <axis xyz="0 1 0"/>
    <limit effort="10" lower="-2.094" upper="0.0872665" velocity="59.2"/>
    <joint_properties friction="0.0"/>
  </joint>
  <link name="l_elbow_fe_link">
    <visual>
      <origin rpy="0 -0 0" xyz="0 0 0"/>
      <geometry>
        <mesh filename="package://meshes/l_elbow_fe_link.stl"/>
      </geometry>
      <material name="dark_gray"/>
    </visual>
    <inertial>
      <origin rpy="0 0 0" xyz="-0.0190443 0 -0.0633779"/>
      <mass value="0.990031"/>
      <inertia ixx="0.00220347" ixy="-2.91162e-08" ixz="-0.000310918" iyy="0.00297439" iyz="2.27665e-07" izz="0.0021045"/>
    </inertial>
  </link>

  <!--=============================== l_wrist_ps (l_wrist_ps_link) ===========================-->
  <joint name="l_wrist_ps" type="revolute">
    <origin rpy="0 0 0" xyz="0 0 0"/>
    <parent link="l_elbow_fe_link"/>
    <child link="l_wrist_ps_link"/>
    <axis xyz="0 0 1"/>
    <limit effort="12" lower="-1.571" upper="1.571" velocity="71"/>
    <joint_properties friction="0.0"/>
  </joint>
  <link name="l_wrist_ps_link">
    <visual>
      <origin rpy="0 0 0" xyz="0 0 0"/>
      <geometry>
        <mesh filename="package://meshes/l_wrist_ps_link.stl"/>
      </geometry>
      <material name="dark_gray"/>
    </visual>
    <inertial>
      <origin rpy="0 0 0" xyz="0.000229308 0.0158433 -0.154"/>
      <mass value="0.64434"/>
      <inertia ixx="0.001" ixy="1.05504e-05" ixz="-5.41208e-06" iyy="0.001" iyz="4.65277e-05" izz="0.001"/>
    </inertial>
  </link>

  <!--=============================== l_wrist_pitch (l_wrist_pitch_link) ===========================-->
  <joint name="l_wrist_pitch" type="revolute">
    <origin rpy="0 0 0" xyz="0 0 -0.1578"/>
    <parent link="l_wrist_ps_link"/>
    <child link="l_wrist_pitch_link"/>
    <axis xyz="0 1 0"/>
    <limit effort="8.8" lower="-1.571" upper="1.571" velocity="76"/>
    <joint_properties friction="0.0"/>
  </joint>
  <link name="l_wrist_pitch_link">
    <inertial>
      <origin rpy="0 0 0" xyz="0 0 0"/>
      <mass value="1e-9"/>
      <inertia ixx="0" ixy="0" ixz="0" iyy="0" iyz="0" izz="0"/>
    </inertial>
  </link>

  <!--=============================== l_wrist_mount (l_sake_gripper_link) ===========================-->
  <joint name="l_wrist_mount" type="fixed">
    <origin rpy="0 0 0" xyz="0 0 0"/>
    <parent link="l_wrist_pitch_link"/>
    <child link="l_sake_gripper_link"/>
  </joint>
  <link name="l_sake_gripper_link">
    <visual>
      <origin rpy="0 0 0" xyz="0 0 0"/>
      <geometry>
        <mesh filename="package://meshes/l_sake_gripper_link.stl"/>
      </geometry>
      <material name="gray"/>
    </visual>
    <inertial>
      <origin rpy="0 0 0" xyz="5.4498e-05 0.000382544 -0.061"/>
      <mass value="0.498"/>
      <inertia ixx="0.00091" ixy="2.81199e-09" ixz="2.07385e-07" iyy="0.0004228" iyz="-5.81044e-06" izz="0.00091"/>
    </inertial>
  </link>

  <!--=============================== l_camera_frame (l_camera) ===========================-->
  <joint name="l_camera_frame" type="fixed">
      <!--circle-->
      <!--<origin rpy="0 0 0" xyz="-0.05535 0 -0.0975"/> -->
      <!--camera (45 deg)-->
      <!--<origin rpy="0 2.355 0" xyz="-0.07267 0 -0.0802"/> -->
      <!--camera (90 deg)-->
      <origin rpy="0 3.14 0" xyz="-0.05535 0 -0.073"/>
    <parent link="l_sake_gripper_link"/>
    <child link="l_camera"/>
    <axis xyz="0 0 0"/>
  </joint>
  <link name="l_camera">
    <inertial>
      <origin rpy="0 0 0" xyz="0 0 0"/>
      <mass value="1e-9"/>
      <inertia ixx="0" ixy="0" ixz="0" iyy="0" iyz="0" izz="0"/>
    </inertial>
    <visual>
      <origin rpy="0 0 0" xyz="0 0 0"/>
      <geometry>
          <sphere radius="0.01"/>
      </geometry>
    </visual>
  </link>

  <!--=============================== l_hand_contact_frame (l_hand_contact) ===========================-->
  <joint name="l_hand_contact_frame" type="fixed">
    <origin rpy="0 0 0" xyz="0 0 -0.150052"/>
    <parent link="l_sake_gripper_link"/>
    <child link="l_hand_contact"/>
    <axis xyz="0 0 0"/>
  </joint>
  <link name="l_hand_contact">
    <inertial>
      <origin rpy="0 0 0" xyz="0 0 0"/>
      <mass value="1e-9"/>
      <inertia ixx="0" ixy="0" ixz="0" iyy="0" iyz="0" izz="0"/>
    </inertial>
  </link>

  <!--=============================== r_shoulder_fe (r_shoulder_fe_link) ===========================-->
  <joint name="r_shoulder_fe" type="revolute">
    <origin rpy="-0.523599 0 0" xyz="-0.05 -0.156 0.2625"/>
    <parent link="torso_link"/>
    <child link="r_shoulder_fe_link"/>
    <axis xyz="0 1 0"/>
    <limit effort="18" lower="-2.26893" upper="0.698132" velocity="47"/>
    <joint_properties friction="0.0"/>
  </joint>
  <link name="r_shoulder_fe_link">
    <visual>
      <origin rpy="0 -0 0" xyz="0 0 0"/>
      <geometry>
        <mesh filename="package://meshes/r_shoulder_fe_link.stl"/>
      </geometry>
      <material name="dark_gray"/>
    </visual>
    <inertial>
      <origin rpy="0 0 0" xyz="-0.0825089 0.0272215 6.40505e-05"/>
      <mass value="1.02127"/>
      <inertia ixx="0.003" ixy="-0.000198378" ixz="3.31293e-05" iyy="0.002" iyz="-3.00004e-06" izz="0.002"/>
    </inertial>
  </link>

  <!--=============================== r_shoulder_aa (r_shoulder_aa_link) ===========================-->
  <joint name="r_shoulder_aa" type="revolute">
    <origin rpy="0.523599 0 0" xyz="0 0 0"/>
    <parent link="r_shoulder_fe_link"/>
    <child link="r_shoulder_aa_link"/>
    <axis xyz="1 0 0"/>
    <limit effort="18" lower="-2.0944" upper="0" velocity="47"/>
    <joint_properties friction="0.0"/>
  </joint>
  <link name="r_shoulder_aa_link">
    <visual>
      <origin rpy="0 0 0" xyz="0 0 0"/>
      <geometry>
        <mesh filename="package://meshes/r_shoulder_aa_link.stl"/>
      </geometry>
      <material name="dark_gray"/>
    </visual>
    <inertial>
      <origin rpy="0 0 0" xyz="0.0189446 0.000135529 0.00688183"/>
      <mass value="0.880498"/>
      <inertia ixx="0.00104194" ixy="5.17675e-06" ixz="-0.000110264" iyy="0.00190054" iyz="6.87354e-06" izz="0.00224159"/>
    </inertial>
  </link>

  <!--=============================== r_shoulder_ie (r_shoulder_ie_link) ===========================-->
  <joint name="r_shoulder_ie" type="revolute">
    <origin rpy="0 0 0" xyz="0 0 0"/>
    <parent link="r_shoulder_aa_link"/>
    <child link="r_shoulder_ie_link"/>
    <axis xyz="0 0 1"/>
    <limit effort="18" lower="-1.5" upper="1.5" velocity="47"/>
    <joint_properties friction="0.0"/>
  </joint>
  <link name="r_shoulder_ie_link">
    <visual>
      <origin rpy="0 0 0" xyz="0 0 0"/>
      <geometry>
        <mesh filename="package://meshes/r_shoulder_ie_link.stl"/>
      </geometry>
      <material name="gray"/>
    </visual>
    <inertial>
      <origin rpy="0 0 0" xyz="-0.00404627 -0.029987 -0.137257"/>
      <mass value="1.21235"/>
      <inertia ixx="0.00490973" ixy="-4.37742e-05" ixz="-6.62765e-05" iyy="0.00459809" iyz="-3.39569e-05" izz="0.002074"/>
    </inertial>
  </link>

  <!--=============================== r_elbow_fe (r_elbow_fe_link) ===========================-->
  <joint name="r_elbow_fe" type="revolute">
    <origin rpy="0 0 0" xyz="0 0 -0.25"/>
    <parent link="r_shoulder_ie_link"/>
    <child link="r_elbow_fe_link"/>
    <axis xyz="0 1 0"/>
    <limit effort="10" lower="-2.094" upper="0.0872665" velocity="59.2"/>
    <joint_properties friction="0.0"/>
  </joint>
  <link name="r_elbow_fe_link">
    <visual>
      <origin rpy="0 -0 0" xyz="0 0 0"/>
      <geometry>
        <mesh filename="package://meshes/r_elbow_fe_link.stl"/>
      </geometry>
      <material name="dark_gray"/>
    </visual>
    <inertial>
      <origin rpy="0 0 0" xyz="-0.0190415 1.75896e-05 -0.0633849"/>
      <mass value="0.990031"/>
      <inertia ixx="0.00220407" ixy="-2.9063e-08" ixz="-0.000310786" iyy="0.00297478" iyz="2.27528e-07" izz="0.00210481"/>
    </inertial>
  </link>

  <!--=============================== r_wrist_ps (r_wrist_ps_link) ===========================-->
  <joint name="r_wrist_ps" type="revolute">
    <origin rpy="0 0 0" xyz="0 0 0"/>
    <parent link="r_elbow_fe_link"/>
    <child link="r_wrist_ps_link"/>
    <axis xyz="0 0 1"/>
    <limit effort="12" lower="-1.571" upper="1.571" velocity="71"/>
    <joint_properties friction="0.0"/>
  </joint>
  <link name="r_wrist_ps_link">
    <visual>
      <origin rpy="0 -0 0" xyz="0 0 0"/>
      <geometry>
        <mesh filename="package://meshes/r_wrist_ps_link.stl"/>
      </geometry>
      <material name="dark_gray"/>
    </visual>
    <inertial>
      <origin rpy="0 0 0" xyz="0.000229308 0.0158433 -0.154481"/>
      <mass value="0.64434"/>
      <inertia ixx="0.001" ixy="5.23851e-06" ixz="-4.22277e-06" iyy="0.001" iyz="3.40912e-05" izz="0.001"/>
    </inertial>
  </link>

  <!--=============================== r_wrist_pitch (r_wrist_pitch_link) ===========================-->
  <joint name="r_wrist_pitch" type="revolute">
    <origin rpy="0 0 0" xyz="0 0 -0.1578"/>
    <parent link="r_wrist_ps_link"/>
    <child link="r_wrist_pitch_link"/>
    <axis xyz="0 1 0"/>
    <limit effort="8.8" lower="-1.571" upper="1.571" velocity="76"/>
    <joint_properties friction="0.0"/>
  </joint>
  <link name="r_wrist_pitch_link">
    <inertial>
      <origin rpy="0 0 0" xyz="0 0 0"/>
      <mass value="1e-9"/>
      <inertia ixx="0" ixy="0" ixz="0" iyy="0" iyz="0" izz="0"/>
    </inertial>
  </link>

  <!--=============================== r_wrist_mount (r_sake_gripper_link) ===========================-->
  <joint name="r_wrist_mount" type="fixed">
    <origin rpy="0 0 0" xyz="0 0 0"/>
    <parent link="r_wrist_pitch_link"/>
    <child link="r_sake_gripper_link"/>
  </joint>
  <link name="r_sake_gripper_link">
    <visual>
      <origin rpy="0 0 0" xyz="0 0 0"/>
      <geometry>
        <mesh filename="package://meshes/r_sake_gripper_link.stl"/>
      </geometry>
      <material name="gray"/>
    </visual>
    <inertial>
      <origin rpy="0 0 0" xyz="5.4498e-05 0.000382544 -0.061"/>
      <mass value="0.498"/>
      <inertia ixx="0.00091" ixy="2.81199e-09" ixz="2.07385e-07" iyy="0.0004228" iyz="-5.81044e-06" izz="0.00091"/>
    </inertial>
  </link>

  <!--=============================== r_camera_frame (r_camera) ===========================-->
  <joint name="r_camera_frame" type="fixed">
      <!--circle-->
      <!--<origin rpy="0 0 0" xyz="-0.05535 0 -0.0975"/> -->
      <!--camera (45 deg)-->
      <!--<origin rpy="0 2.355 0" xyz="-0.07267 0 -0.0802"/> -->
      <!--camera (90 deg)-->
      <origin rpy="0 3.14 0" xyz="-0.05535 0 -0.073"/>
    <parent link="r_sake_gripper_link"/>
    <child link="r_camera"/>
    <axis xyz="0 0 0"/>
  </joint>
  <link name="r_camera">
    <inertial>
      <origin rpy="0 0 0" xyz="0 0 0"/>
      <mass value="1e-9"/>
      <inertia ixx="0" ixy="0" ixz="0" iyy="0" iyz="0" izz="0"/>
    </inertial>
    <visual>
      <origin rpy="0 0 0" xyz="0 0 0"/>
      <geometry>
          <sphere radius="0.01"/>
      </geometry>
    </visual>
  </link>

  <!--=============================== r_hand_contact_frame (r_hand_contact) ===========================-->
  <joint name="r_hand_contact_frame" type="fixed">
    <origin rpy="0 0 0" xyz="0 0 -0.150052"/>
    <parent link="r_sake_gripper_link"/>
    <child link="r_hand_contact"/>
    <axis xyz="0 0 0"/>
  </joint>
  <link name="r_hand_contact">
    <inertial>
      <origin rpy="0 0 0" xyz="0 0 0"/>
      <mass value="1e-9"/>
      <inertia ixx="0" ixy="0" ixz="0" iyy="0" iyz="0" izz="0"/>
    </inertial>
  </link>

  <!--=============================== l_hip_ie (l_hip_ie_link) ===========================-->
  <joint name="l_hip_ie" type="revolute">
    <origin rpy="0.523599 0 0" xyz="0 0.06 -0.0893782"/>
    <parent link="torso_link"/>
    <child link="l_hip_ie_link"/>
    <axis xyz="0 0 1"/>
    <limit effort="44" lower="-0.872665" upper="0.872665" velocity="8.1"/>
    <joint_properties friction="0.0"/>
  </joint>
  <link name="l_hip_ie_link">
    <visual>
      <origin rpy="0 0 0" xyz="0 0 0"/>
      <geometry>
        <mesh filename="package://meshes/l_hip_ie_link.stl"/>
      </geometry>
      <material name="dark_gray"/>
    </visual>
    <inertial>
      <origin rpy="0 0 0" xyz="-0.00363703 0.00531284 -0.0260463"/>
      <mass value="0.162"/>
      <inertia ixx="136.77063e-06" ixy="-12.07781e-06" ixz="18.69536e-06" iyy="229.3943e-06" iyz="26.13639e-06" izz="196.36211e-06"/>
    </inertial>
  </link>

  <!--=============================== l_hip_aa (l_hip_aa_link) ===========================-->
  <joint name="l_hip_aa" type="revolute">
    <origin rpy="-0.523599 0 0" xyz="0 0 -0.07"/>
    <parent link="l_hip_ie_link"/>
    <child link="l_hip_aa_link"/>
    <axis xyz="1 0 0"/>
    <limit effort="56" lower="-0.261799" upper="0.785398" velocity="5.1"/>
    <joint_properties friction="0.0"/>
  </joint>
  <link name="l_hip_aa_link">
    <visual>
      <origin rpy="0 -0 0" xyz="0 0 0"/>
      <geometry>
        <mesh filename="package://meshes/l_hip_aa_link.stl"/>
      </geometry>
      <material name="dark_gray"/>
    </visual>
    <inertial>
      <origin rpy="0 0 0" xyz="-0.000880455 0.00182239 -0.00110234"/>
      <mass value="0.912"/>
      <inertia ixx="870.08327e-06" ixy="36.28214e-06" ixz="12.89916e-06" iyy="865.69602e-06" iyz="26.99886e-06" izz="1023.81075e-06"/>
    </inertial>
  </link>

  <!--=============================== l_hip_fe (l_hip_fe_link) ===========================-->
  <joint name="l_hip_fe" type="revolute">
    <origin rpy="0 0 0" xyz="0 0 0"/>
    <parent link="l_hip_aa_link"/>
    <child link="l_hip_fe_link"/>
    <axis xyz="0 1 0"/>
    <limit effort="59.6" lower="-1.52716" upper="0.523599" velocity="36.7"/>
    <joint_properties friction="0.0"/>
  </joint>
  <link name="l_hip_fe_link">
    <visual>
      <origin rpy="0 0 0" xyz="0 0 0"/>
      <geometry>
        <mesh filename="package://meshes/l_hip_fe_link.stl"/>
      </geometry>
      <material name="gray"/>
    </visual>
    <inertial>
      <origin rpy="0 0 0" xyz="0.00193727 -0.00408989 -0.1636"/>
      <mass value="5.0"/>
      <inertia ixx="61021.51e-06" ixy="-47.486e-06" ixz="578.602e-06" iyy="67907.577e-06" iyz="3610.535e-06" izz="14521.809e-06"/>
    </inertial>
  </link>

  <!--=============================== l_knee_fe_jp (l_knee_fe_lp) ===========================-->
  <joint name="l_knee_fe_jp" type="revolute">
    <origin rpy="0 0 0" xyz="0 0 -0.324231"/>
    <parent link="l_hip_fe_link"/>
    <child link="l_knee_fe_lp"/>
    <axis xyz="0 1 0"/>
    <limit effort="40.85" lower="-0.0872665" upper="1.52716" velocity="13.35"/>
    <joint_properties friction="0.0"/>
  </joint>
  <link name="l_knee_fe_lp">
    <visual>
      <origin rpy="0 -0 0" xyz="0 0 0"/>
      <geometry>
        <mesh filename="package://meshes/l_knee_fe_lp.stl"/>
      </geometry>
      <material name="dark_gray"/>
    </visual>
    <inertial>
      <origin rpy="0 0 0" xyz="-7.68312e-09 0.0147631 -0.0260394"/>
      <mass value="0.211"/>
      <inertia ixx="778.97283e-06" ixy="0.00028e-06" ixz="0.00028e-06" iyy="447.80329e-06" iyz="3.84258e-06" izz="484.80585e-06"/>
    </inertial>
  </link>

  <!--=============================== l_knee_adj (l_knee_adj_link) ===========================-->
  <joint name="l_knee_adj" type="fixed">
    <origin rpy="0 0 0" xyz="0 0 -0.0557693"/>
    <parent link="l_knee_fe_lp"/>
    <child link="l_knee_adj_link"/>
  </joint>
  <link name="l_knee_adj_link">
    <visual>
      <origin rpy="0 0 0" xyz="0 0 0"/>
      <geometry>
        <mesh filename="package://meshes/l_knee_adj_link.stl"/>
      </geometry>
      <material name="dark_gray"/>
    </visual>
    <inertial>
      <origin rpy="0 0 0" xyz="0.00907506 -0.006495 -0.017049"/>
      <mass value="0.156"/>
      <inertia ixx="461.2405e-06" ixy="20.74097e-06" ixz="-22.60628e-06" iyy="252.3969e-06" iyz="36.06734e-06" izz="342.40347e-06"/>
    </inertial>
  </link>

  <!--=============================== l_knee_fe_jd (l_knee_fe_ld) ===========================-->
  <!-- NOTE: If you're NOT using Apptronik's simulator, please uncomment line 716 and use that, instead of line 717 -->
  <joint name="l_knee_fe_jd" type="revolute">
    <!-- <origin xyz="${0 + 0*l_knee_adj_param} ${0.00599 + 0.0537 * l_knee_adj_param} ${-0.1115386 + -0.9985 * l_knee_adj_param}" rpy="-1.90275e-16 1.31839e-16 2.80923e-17" /> -->
    <origin rpy="0 0 0" xyz="0.0 0.0 -0.1117386"/>
    <parent link="l_knee_fe_lp"/>
    <child link="l_knee_fe_ld"/>
    <axis xyz="0 1 0"/>
    <limit effort="40.85" lower="-0.0872665" upper="1.52716" velocity="13.35"/>
  </joint>
  <link name="l_knee_fe_ld">
    <visual>
      <origin rpy="0 -0 0" xyz="0 0 0"/>
      <geometry>
        <mesh filename="package://meshes/l_knee_fe_ld.stl"/>
      </geometry>
      <material name="gray"/>
    </visual>
    <inertial>
      <origin rpy="0 0 0" xyz="0.00588785 0.0041898 -0.0805522"/>
      <mass value="2.5"/>
      <inertia ixx="9986.75806e-06" ixy="-264.73832e-06" ixz="40.35627e-06" iyy="11291.38892e-06" iyz="725.40626e-06" izz="4054.98067e-06"/>
    </inertial>
  </link>

  <!--=============================== l_ankle_fe (l_ankle_fe_link) ===========================-->
  <!-- NOTE: If you're NOT using Apptronik's simulator, please uncomment line 753 and use that, instead of line 754 -->
  <joint name="l_ankle_fe" type="revolute">
    <!-- <origin xyz="-6.26776e-17 -1.80411e-16 -0.248231" rpy="2.01226e-15 1.44763e-15 -7.77124e-18" /> -->
    <origin rpy="0 0 0" xyz="0 0.00599 -0.248231"/>
    <parent link="l_knee_fe_ld"/>
    <child link="l_ankle_fe_link"/>
    <axis xyz="0 1 0"/>
    <limit effort="44" lower="-1.5708" upper="1.0472" velocity="8.1"/>
    <joint_properties friction="0.0"/>
  </joint>
  <link name="l_ankle_fe_link">
    <visual>
      <origin rpy="0 -0 0" xyz="0 0 0"/>
      <geometry>
        <mesh filename="package://meshes/l_ankle_fe_link.stl"/>
      </geometry>
      <material name="dark_gray"/>
    </visual>
    <inertial>
      <origin rpy="0 0 0" xyz="-0.000143954 0.0286126 -0.000732972"/>
      <mass value="0.172"/>
      <inertia ixx="83.52192e-06" ixy="-0.09751e-06" ixz="2.33379e-06" iyy="54.43219e-06" iyz="0.68506e-06" izz="95.29953e-06"/>
    </inertial>
  </link>

  <!--=============================== l_ankle_ie (l_ankle_ie_link) ===========================-->
  <joint name="l_ankle_ie" type="revolute">
    <origin rpy="0 0 0" xyz="0 0 0"/>
    <parent link="l_ankle_fe_link"/>
    <child link="l_ankle_ie_link"/>
    <axis xyz="1 0 0"/>
    <limit effort="30" lower="-0.785398" upper="0.261799" velocity="11.1"/>
    <joint_properties friction="0.0"/>
  </joint>
  <link name="l_ankle_ie_link">
    <visual>
      <origin rpy="0 -0 0" xyz="0 0 0"/>
      <geometry>
        <mesh filename="package://meshes/l_ankle_ie_link.stl"/>
      </geometry>
      <material name="dark_gray"/>
    </visual>
    <collision>
      <origin rpy="0 -0 0" xyz="0 -0.005 -0.046"/>
      <geometry>
        <box size="0.2 0.1 0.0591"/>
      </geometry>
    </collision>
    <inertial>
      <origin rpy="0 0 0" xyz="-0.00321864 -0.00678326 -0.0440152"/>
      <mass value="0.478"/>
      <inertia ixx="1064.65492e-06" ixy="-25.85803e-06" ixz="148.2107e-06" iyy="1820.44891e-06" iyz="145.81372e-06" izz="1268.38379e-06"/>
    </inertial>
  </link>

  <!--=============================== l_foot_contact_frame (l_foot_contact) ===========================-->
  <joint name="l_foot_contact_frame" type="fixed">
    <origin rpy="0 0 0" xyz="0 0 -0.076"/>
    <parent link="l_ankle_ie_link"/>
    <child link="l_foot_contact"/>
  </joint>
  <link name="l_foot_contact">
    <inertial>
      <origin rpy="0 0 0" xyz="0 0 0"/>
      <mass value="1e-9"/>
      <inertia ixx="0" ixy="0" ixz="0" iyy="0" iyz="0" izz="0"/>
    </inertial>
  </link>

  <!--=============================== r_hip_ie (r_hip_ie_link) ===========================-->
  <joint name="r_hip_ie" type="revolute">
    <origin rpy="-0.523599 0 0" xyz="0 -0.06 -0.0893782"/>
    <parent link="torso_link"/>
    <child link="r_hip_ie_link"/>
    <axis xyz="0 0 1"/>
    <limit effort="44" lower="-0.872665" upper="0.872665" velocity="8.1"/>
    <joint_properties friction="0.0"/>
  </joint>
  <link name="r_hip_ie_link">
    <visual>
      <origin rpy="0 -0 0" xyz="0 0 0"/>
      <geometry>
        <mesh filename="package://meshes/r_hip_ie_link.stl"/>
      </geometry>
      <material name="dark_gray"/>
    </visual>
    <inertial>
      <origin rpy="0 0 0" xyz="-0.00363703 -0.00531284 -0.0260652"/>
      <mass value="0.162"/>
      <inertia ixx="136.77063e-06" ixy="12.07781e-06" ixz="18.69536e-06" iyy="229.3943e-06" iyz="-26.13639e-06" izz="196.36211e-06"/>
    </inertial>
  </link>

  <!--=============================== r_hip_aa (r_hip_aa_link) ===========================-->
  <joint name="r_hip_aa" type="revolute">
    <origin rpy="0.523599 0 0" xyz="0 0 -0.07"/>
    <parent link="r_hip_ie_link"/>
    <child link="r_hip_aa_link"/>
    <axis xyz="1 0 0"/>
    <limit effort="56" lower="-0.785398" upper="0.261799" velocity="5.1"/>
    <joint_properties friction="0.0"/>
  </joint>
  <link name="r_hip_aa_link">
    <visual>
      <origin rpy="0 -0 0" xyz="0 0 0"/>
      <geometry>
        <mesh filename="package://meshes/r_hip_aa_link.stl"/>
      </geometry>
      <material name="dark_gray"/>
    </visual>
    <inertial>
      <origin rpy="0 0 0" xyz="-0.000880446 -0.00180849 -0.00110234"/>
      <mass value="0.912"/>
      <inertia ixx="8.7008327e-04" ixy="-3.628214e-05" ixz="1.289916e-05" iyy="8.6569602e-04" iyz="-2.699886e-05" izz="1.02381075e-03"/>
    </inertial>
  </link>

  <!--=============================== r_hip_fe (r_hip_fe_link) ===========================-->
  <joint name="r_hip_fe" type="revolute">
    <origin rpy="0 0 0" xyz="0 0 0"/>
    <parent link="r_hip_aa_link"/>
    <child link="r_hip_fe_link"/>
    <axis xyz="0 1 0"/>
    <limit effort="59.6" lower="-1.52716" upper="0.523599" velocity="36.7"/>
    <joint_properties friction="0.0"/>
  </joint>
  <link name="r_hip_fe_link">
    <visual>
      <origin rpy="0 -0 0" xyz="0 0 0"/>
      <geometry>
        <mesh filename="package://meshes/r_hip_fe_link.stl"/>
      </geometry>
      <material name="gray"/>
    </visual>
    <inertial>
      <origin rpy="0 0 0" xyz="0.00193727 0.00408989 -0.1636"/>
      <mass value="5.0"/>
      <inertia ixx="61021.51e-06" ixy="47.486e-06" ixz="578.602e-06" iyy="67907.577e-06" iyz="-3610.535e-06" izz="14521.809e-06"/>
    </inertial>
  </link>

  <!--=============================== r_knee_fe_jp (r_knee_fe_lp) ===========================-->
  <joint name="r_knee_fe_jp" type="revolute">
    <origin rpy="0 0 0" xyz="0 0 -0.324231"/>
    <parent link="r_hip_fe_link"/>
    <child link="r_knee_fe_lp"/>
    <axis xyz="0 1 0"/>
    <limit effort="40.85" lower="-0.0872665" upper="1.52716" velocity="13.35"/>
    <joint_properties friction="0.0"/>
  </joint>
  <link name="r_knee_fe_lp">
    <visual>
      <origin rpy="0 -0 0" xyz="0 0 0"/>
      <geometry>
        <mesh filename="package://meshes/r_knee_fe_lp.stl"/>
      </geometry>
      <material name="dark_gray"/>
    </visual>
    <inertial>
      <origin rpy="0 0 0" xyz="4.68497e-09 -0.0147631 -0.0260394"/>
      <mass value="0.211"/>
      <inertia ixx="778.97283e-06" ixy="0.00028e-06" ixz="-0.00028e-06" iyy="447.80329e-06" iyz="-3.84258e-06" izz="484.80585e-06"/>
    </inertial>
  </link>

  <!--=============================== r_knee_adj (r_knee_adj_link) ===========================-->
  <joint name="r_knee_adj" type="fixed">
    <origin rpy="0 0 0" xyz="0 0 -0.0557693"/>
    <parent link="r_knee_fe_lp"/>
    <child link="r_knee_adj_link"/>
  </joint>
  <link name="r_knee_adj_link">
    <visual>
      <origin rpy="0 -0 0" xyz="0 0 0"/>
      <geometry>
        <mesh filename="package://meshes/r_knee_adj_link.stl"/>
      </geometry>
      <material name="dark_gray"/>
    </visual>
    <inertial>
      <origin rpy="0 0 0" xyz="0.00907522 0.00649535 -0.0170486"/>
      <mass value="0.156"/>
      <inertia ixx="461.2405e-06" ixy="-20.74097e-06" ixz="-22.60628e-06" iyy="252.3969e-06" iyz="-36.06734e-06" izz="342.40347e-06"/>
    </inertial>
  </link>

  <!--=============================== r_knee_fe_jd (r_knee_fe_ld) ===========================-->
  <!-- NOTE: If you're NOT using Apptronik's simulator, please uncomment line 1019 and use that, instead of line 1020 -->
  <joint name="r_knee_fe_jd" type="revolute">
    <!-- <origin xyz="${0 + 0 * r_knee_adj_param} ${-0.006 + -0.0537 * r_knee_adj_param} ${-0.1115386 + -0.9985 * r_knee_adj_param}" rpy="1.06003e-30 6.64446e-33 -5.70613e-32" /> -->
    <origin rpy="0 0 0" xyz="0 0 -0.1117386"/>
    <parent link="r_knee_fe_lp"/>
    <child link="r_knee_fe_ld"/>
    <axis xyz="0 1 0"/>
    <limit effort="40.85" lower="-0.0872665" upper="1.52716" velocity="13.35"/>
    <joint_properties friction="0.0"/>
  </joint>
  <link name="r_knee_fe_ld">
    <visual>
      <origin rpy="0 -0 0" xyz="0 0 0"/>
      <geometry>
        <mesh filename="package://meshes/r_knee_fe_ld.stl"/>
      </geometry>
      <material name="gray"/>
    </visual>
    <inertial>
      <origin rpy="0 0 0" xyz="0.00590237 -0.00420298 -0.0805676"/>
      <mass value="2.5"/>
      <inertia ixx="9986.75806e-06" ixy="264.73832e-06" ixz="40.35627e-06" iyy="11291.38892e-06" iyz="-725.40626e-06" izz="4054.98067e-06"/>
    </inertial>
  </link>

  <!--=============================== r_ankle_fe (r_ankle_fe_link) ===========================-->
  <!-- NOTE: If you're NOT using Apptronik's simulator, please uncomment line 1057 and use that, instead of line 1058 -->
  <joint name="r_ankle_fe" type="revolute">
    <!-- <origin xyz="-1.70255e-16 -9.71445e-17 -0.248231" rpy="-1.09947e-29 -6.39256e-14 1.4244e-16" /> -->
    <origin rpy="0 0 0" xyz="0 -0.006 -0.248231"/>
    <parent link="r_knee_fe_ld"/>
    <child link="r_ankle_fe_link"/>
    <axis xyz="0 1 0"/>
    <limit effort="44" lower="-1.5708" upper="1.0472" velocity="8.1"/>
    <joint_properties friction="0.0"/>
  </joint>
  <link name="r_ankle_fe_link">
    <visual>
      <origin rpy="0 -0 0" xyz="0 0 0"/>
      <geometry>
        <mesh filename="package://meshes/r_ankle_fe_link.stl"/>
      </geometry>
      <material name="dark_gray"/>
    </visual>
    <inertial>
      <origin rpy="0 0 0" xyz="-0.00026965 -0.0286127 -0.000732675"/>
      <mass value="0.172"/>
      <inertia ixx="83.52192e-06" ixy="0.09751e-06" ixz="2.33379e-06" iyy="54.43219e-06" iyz="-0.68506e-06" izz="95.29953e-06"/>
    </inertial>
  </link>

  <!--=============================== r_ankle_ie (r_ankle_ie_link) ===========================-->
  <joint name="r_ankle_ie" type="revolute">
    <origin rpy="0 0 0" xyz="0 0 0"/>
    <parent link="r_ankle_fe_link"/>
    <child link="r_ankle_ie_link"/>
    <axis xyz="1 0 0"/>
    <limit effort="30" lower="-0.261799" upper="0.785398" velocity="11.1"/>
    <joint_properties friction="0.0"/>
  </joint>
  <link name="r_ankle_ie_link">
    <visual>
      <origin rpy="0 -0 0" xyz="0 0 0"/>
      <geometry>
        <mesh filename="package://meshes/r_ankle_ie_link.stl"/>
      </geometry>
      <material name="dark_gray"/>
    </visual>
    <collision>
      <origin rpy="0 -0 0" xyz="0 0.005 -0.046"/>
      <geometry>
        <box size="0.2 0.1 0.0591"/>
      </geometry>
    </collision>
    <inertial>
      <origin rpy="0 0 0" xyz="-0.00321562 0.00678152 -0.0440164"/>
      <mass value="0.478"/>
      <inertia ixx="1064.65492e-06" ixy="25.85803e-06" ixz="148.2107e-06" iyy="1820.44891e-06" iyz="-145.81372e-06" izz="1268.38379e-06"/>
    </inertial>
  </link>

  <!--=============================== r_foot_contact_frame (r_foot_contact) ===========================-->
  <joint name="r_foot_contact_frame" type="fixed">
    <origin rpy="0 0 0" xyz="0 0 -0.076"/>
    <parent link="r_ankle_ie_link"/>
    <child link="r_foot_contact"/>
  </joint>
  <link name="r_foot_contact">
    <inertial>
      <origin rpy="0 0 0" xyz="0 0 0"/>
      <mass value="1e-9"/>
      <inertia ixx="0" ixy="0" ixz="0" iyy="0" iyz="0" izz="0"/>
    </inertial>
  </link>
  <!--=============================== torso_imu_frame (torso_imu) ===========================-->
  <joint name="torso_imu_frame" type="fixed">
    <origin rpy="3.14159 0 3.14159" xyz="0 0 -0.09"/>
    <parent link="torso_link"/>
    <child link="torso_imu"/>
    <axis xyz="0 0 0"/>
  </joint>
  <link name="torso_imu">
    <inertial>
      <origin rpy="0 0 0" xyz="0 0 0"/>
      <mass value="1e-9"/>
      <inertia ixx="0" ixy="0" ixz="0" iyy="0" iyz="0" izz="0"/>
    </inertial>
  </link>
</robot>
